Workbook

Sheet feature_catalog
A1: source_column | B1: feature_name | C1: type | D1: description | E1: exemple | F1: relevant_roles | G1: inverted | H1: feat_col | I1: z_col
A2: goals | B2: goals_p90 | C2: vol | D2: But marqué — ballon franchissant entièrement la ligne de but, attribué au dernier joueur ayant touché le ballon intentionnellement | E2: Haaland reprend un centre de Bernardo Silva du pied droit — but | F2: CF|W|AM|SS | G2: False | H2: feat_goals_p90 | I2: z_goals_p90
A3: expectedGoals | B3: xg_p90 | C3: vol | D3: Probabilité qu'un tir donné se transforme en but, calculée sur la base de situations similaires dans la base historique Opta (~1 million de tirs). Facteurs : position, partie du corps, type de situation (ouvert/corner/coup franc), pression défensive. Échelle 0-1. | E3: Tir du pied droit à 12m face au but, sans gardien sorti : xG=0.38. Même tir de l'extérieur de la surface : xG=0.05 | F3: CF|W|AM|SS|CM | G3: False | H3: feat_xg_p90 | I3: z_xg_p90
A4: np_xg | B4: npxg_p90 | C4: vol | D4: xG total du joueur sur la saison, pénaltys exclus. Les pénaltys étant des tirs à xG fixe ~0.76 quelle que soit la qualité du tireur, ils sont retirés pour mesurer la vraie qualité des occasions en jeu ouvert. | E4: Joueur avec 18 xG dont 4 sur pénaltys → npxG = 14 | F4: CF|W|AM|SS|CM | G4: False | H4: feat_npxg_p90 | I4: z_npxg_p90
A5: xGChain_us | B5: xgchain_p90 | C5: vol | D5: Somme des xG de toutes les occasions auxquelles le joueur a participé dans la séquence de jeu, qu'il ait tiré, passé, ou simplement touché le ballon à n'importe quel moment de l'action. Très inclusif. | E5: Modric touche le ballon 3 passes avant le tir de Benzema (xG=0.25) → Modric reçoit 0.25 dans son xGChain | F5: CF|W|AM|CM|DM|FB | G5: False | H5: feat_xgchain_p90 | I5: z_xgchain_p90
A6: xGBuildup_us | B6: xgbuildup_p90 | C6: vol | D6: xGChain moins la contribution directe du tireur (xG) et du passeur décisif (xA). Mesure exclusivement les touches 'invisibles' en amont de la phase finale — la contribution à la construction profonde. | E6: Cancelo → De Bruyne → Haaland (but, xG=0.45). Cancelo : xGBuildup=0.45. De Bruyne : xGBuildup=0 (passeur déc. exclu). Haaland : xGBuildup=0 (tireur exclu) | F6: CM|DM|CB|FB|AM | G6: False | H6: feat_xgbuildup_p90 | I6: z_xgbuildup_p90
A7: totalShots | B7: shots_p90 | C7: vol | D7: Toute tentative délibérée de marquer, qu'elle soit cadrée, non-cadrée, bloquée ou sur le poteau. Exclut : les centres rentrants comptés comme but, les dégagements comptés comme tir. | E7: Frappe de 25m qui finit en tribunes = 1 tir. Tir bloqué par un défenseur = 1 tir (mais pas cadré) | F7: CF|W|AM | G7: False | H7: feat_shots_p90 | I7: z_shots_p90
A8: shotsFromInsideTheBox | B8: shots_inside_p90 | C8: vol | D8: Tirs tentés depuis l'intérieur de la surface de réparation (18 yards). Sous-ensemble de totalShots mesurant la présence offensive dans la zone de vérité, indépendamment de la précision. | E8: Haaland contrôle dans la surface à 7m et frappe au but = 1 tir depuis l'intérieur de la surface | F8: CF|W|AM | G8: False | H8: feat_shots_inside_p90 | I8: z_shots_inside_p90
A9: headedGoals | B9: headed_goals_p90 | C9: vol | D9: Buts marqués de la tête — sous-ensemble de goals attribués à une touche de tête intentionnelle. Indicateur de domination aérienne offensive. | E9: Giroud détourne un corner de la tête en haut du filet = 1 headed goal | F9: CF|CD | G9: False | H9: feat_headed_goals_p90 | I9: z_headed_goals_p90
A10: _npxg_proxy_p90 | B10: npxg_proxy_p90 | C10: vol | D10: Proxy npxG calculé depuis les données Opta : xG total (expectedGoals) moins la contribution estimée des pénaltys (penaltiesTaken × 0.76). Clip à 0 pour éviter les valeurs négatives. | E10: Joueur avec expectedGoals=12.5 et penaltiesTaken=3 → npxg_proxy = 12.5 − 3×0.76 = 10.22 | F10: CF|W|AM|SS|CM | G10: False | H10: feat_npxg_proxy_p90 | I10: z_npxg_proxy_p90
A11: shotsOnTarget | B11: shots_ot_p90 | C11: vol | D11: Tir cadré = tir qui serait rentré sans intervention du gardien ou du dernier défenseur. Inclut les buts. Exclut les tirs bloqués par un défenseur ordinaire (non dernier défenseur) et les tirs sur le poteau. | E11: Tir stoppé par le gardien = cadré. Tir bloqué par un défenseur en dehors de la ligne = non cadré. Tir sur le poteau = non cadré | F11: CF|W|AM | G11: False | H11: feat_shots_ot_p90 | I11: z_shots_ot_p90
A12: goalConversionPercentage | B12: goal_conv_pct | C12: pct | D12: Buts divisés par tirs totaux tentés, exprimé en pourcentage. Mesure l'efficacité brute de finition. Ne tient pas compte de la qualité des occasions (contrairement à xG). | E12: 10 buts sur 50 tirs = 20%. Valeur moyenne PL ≈ 10-12% | F12: CF|W|AM | G12: False | H12: feat_goal_conv_pct | I12: z_goal_conv_pct
... A96: market_value | B96: market_value | C96: raw | D96: Estimation de la valeur marchande actuelle du joueur par la communauté Transfermarkt, mise à jour périodiquement. Basée sur l'âge, les performances, le contrat restant, l'inflation du marché. N'est pas une valeur contractuelle — c'est une estimation de ce qu'un club paierait. | E96: Bellingham évalué 200M€ = estimation TM communauté, pas valeur contractuelle. Kane à 30 ans : 80M€ vs 150M€ à 27 ans (décote âge) | F96: ALL | G96: False | H96: feat_market_value | I96: z_market_value
A97: derived | B97: np_goals_minus_npxg | C97: derived | D97: Différentiel de finition : buts hors-pénalty par 90 min moins npxG par 90 min (source Understat). Valeur positive = surperforme ses xG (bon finisseur). Valeur négative = sous-performe. Calculé comme npGoals_p90 - npxg_p90, où npGoals = goals - penalty_goals. | E97: Haaland npGoals_p90=0.85, npxg_p90=0.62 → différentiel=+0.23 (excellent finisseur). Joueur moyen ≈ 0. Buteur chanceux ≈ -0.10 | F97: CF|W|AM|SS | G97: FALSE | H97: feat_np_goals_minus_npxg | I97: z_np_goals_minus_npxg
A98: progressiveCarries | B98: prog_carries_p90 | C98: vol | D98: Conduites progressives par 90 min — conduites de balle avançant d'au moins 10 yards vers le but adverse (ou entrant dans la surface de réparation). Mesure la capacité à porter le ballon dans le dos de la défense et créer des situations dangeureuses par la percussion balle au pied. | E98: Mbappé part côté gauche, conduit 15m vers l'intérieur et arrive à l'entrée de la surface = 1 progressive carry. Vinicius : 6-8 progressive carries/match = profil percuteur élite | F98: W|CF|AM|CM|FB | G98: FALSE | H98: feat_prog_carries_p90 | I98: z_prog_carries_p90
A99: touchesInBox | B99: touches_box_p90 | C99: vol | D99: Touches de balle dans la surface de réparation adverse (18 yards) par 90 min. Mesure la présence physique dans la zone de vérité — combinaison de courses, de remises, de fixations et de tirs depuis la surface. Indicateur clé pour les avant-centres et ailiers qui finissent. | E99: Giroud reçoit un centre dans la surface, remet de la tête = 1 touch in box. Haaland contrôle et frappe = 1 touch in box. Valeur top CF PL ≈ 6-10/match | F99: CF|W|AM|SS | G99: FALSE | H99: feat_touches_box_p90 | I99: z_touches_box_p90

Sheet gardien_classique
A1: source_column | B1: feature_name | C1: type | D1: description | E1: exemple | F1: relevant_roles | G1: inverted | H1: feat_col | I1: z_col | J1: source_column | K1: Pondération
A2: accuratePasses | B2: acc_passes_p90 | C2: vol | D2: Nombre absolu de passes réussies sur la saison — passe qu'un coéquipier contrôle. Converti en per-90 pour la comparaison inter-joueurs. Exclut les corners, remises en jeu et dégagements gardien. | E2: Kroos : 85 passes réussies en 90min = 85 acc_passes pour ce match. Moyenne DM = 60-80 per-90 | F2: CM|DM|CB|AM | G2: FALSE | H2: feat_acc_passes_p90 | I2: z_acc_passes_p90 | J2: accuratePasses | K2: 1 | L2: =IFERROR(_xlfn.XLOOKUP(J2,feature_catalog!A:A,feature_catalog!A:A),"") -> accuratePasses
A3: accuratePassesPercentage | B3: pass_acc_pct | C3: pct | D3: Passes réussies divisées par passes tentées. Une passe est réussie si un coéquipier la contrôle. Exclut les corners, remises en jeu, dégagements du gardien et centres (comptés séparément). | E3: Kroos : 85 passes réussies / 90 tentées = 94.4%. Moyenne DM Premier League ≈ 82% | F3: CM|DM|CB|FB|AM|GK | G3: FALSE | H3: feat_pass_acc_pct | I3: z_pass_acc_pct | J3: accuratePassesPercentage | L3: =IFERROR(_xlfn.XLOOKUP(J3,feature_catalog!A:A,feature_catalog!A:A),"") -> accuratePassesPercentage
A4: accurateLongBalls | B4: long_balls_p90 | C4: vol | D4: Passes longues réussies — ballon joué en hauteur sur une distance significative (généralement >32m) récupéré par un coéquipier. Comptées en absolu per-90. | E4: Rúben Dias joue 8 longues passes dont 6 arrivent à un coéquipier = 6 long balls réussies | F4: CB|DM|GK|CM | G4: FALSE | H4: feat_long_balls_p90 | I4: z_long_balls_p90 | J4: accurateLongBalls | L4: =IFERROR(_xlfn.XLOOKUP(J4,feature_catalog!A:A,feature_catalog!A:A),"") -> accurateLongBalls
A5: accurateLongBallsPercentage | B5: long_balls_pct | C5: pct | D5: Passes longues réussies sur passes longues tentées. Une passe longue est définie par Opta comme un ballon joué en hauteur sur une distance significative (généralement >32m). Indicateur clé des CBs relanceurs et gardiens modernes. | E5: Rúben Dias joue 8 longues passes, 6 arrivent à un coéquipier = 75% long balls | F5: CB|DM|GK|CM | G5: FALSE | H5: feat_long_balls_pct | I5: z_long_balls_pct | J5: accurateLongBallsPercentage | K5: 1 | L5: =IFERROR(_xlfn.XLOOKUP(J5,feature_catalog!A:A,feature_catalog!A:A),"") -> accurateLongBallsPercentage
A6: errorLeadToGoal | B6: errors_goal_p90 | C6: vol | D6: Erreur individuelle d'un joueur menant DIRECTEMENT à un but encaissé. L'erreur doit être la cause directe sans phase de jeu intermédiaire. Très rare — 0 à 2 occurrences par saison pour la plupart des joueurs. | E6: Maguire perd le ballon dans sa propre surface, l'adversaire marque immédiatement = 1 errorLeadToGoal. Feature à inverser | F6: CD|GK|FB | G6: TRUE | H6: feat_errors_goal_p90 | I6: z_errors_goal_p90 | J6: errorLeadToGoal | L6: =IFERROR(_xlfn.XLOOKUP(J6,feature_catalog!A:A,feature_catalog!A:A),"") -> errorLeadToGoal
A7: errorLeadToShot | B7: errors_shot_p90 | C7: vol | D7: Erreur menant DIRECTEMENT à un tir adverse, but ou non. Sur-ensemble de errorLeadToGoal — chaque errorLeadToGoal est aussi un errorLeadToShot mais pas l'inverse. Légèrement plus fréquent (2-6/saison). | E7: Stones glisse et offre le ballon à Salah qui tire (gardien arrête) = 1 errorLeadToShot mais pas errorLeadToGoal | F7: CD|GK|FB | G7: TRUE | H7: feat_errors_shot_p90 | I7: z_errors_shot_p90 | J7: errorLeadToShot | K7: 3 | L7: =IFERROR(_xlfn.XLOOKUP(J7,feature_catalog!A:A,feature_catalog!A:A),"") -> errorLeadToShot
A8: headedClearances | B8: headed_clear_p90 | C8: vol | D8: Sous-ensemble des clearances : dégagements effectués de la tête uniquement. Indicateur de domination aérienne défensive dans la surface propre. | E8: Dias dégage un corner adverse de la tête = 1 headed clearance | F8: CB|GK | G8: FALSE | H8: feat_headed_clear_p90 | I8: z_headed_clear_p90 | J8: headedClearances | L8: =IFERROR(_xlfn.XLOOKUP(J8,feature_catalog!A:A,feature_catalog!A:A),"")
A9: saves | B9: saves_p90 | C9: vol | D9: Arrêts réalisés — tirs cadrés adverses stoppés par le gardien. Comptés uniquement sur les tirs qui auraient constitué un but sans l'intervention. Corrélé au volume de tirs adverses reçus. | E9: Alisson arrête un tir de Salah au premier poteau = 1 save. Alisson dévie un tir qui allait à côté = 0 save (pas cadré) | F9: GK | G9: FALSE | H9: feat_saves_p90 | I9: z_saves_p90 | J9: saves | L9: =IFERROR(_xlfn.XLOOKUP(J9,feature_catalog!A:A,feature_catalog!A:A),"") -> saves
A10: cleanSheet | B10: clean_sheets_p90 | C10: vol | D10: Match sans but encaissé — gardien ayant tenu sa cage à zéro pour la totalité du match joué. Per-90 utilisé comme proportion de matchs à zéro. Corrélé à la qualité défensive collective. | E10: Ederson joue 90min sans encaisser = 1 cleanSheet. Ederson sort à la 80e (0-0), remplaçant encaisse = pas de cleanSheet | F10: GK | G10: FALSE | H10: feat_clean_sheets_p90 | I10: z_clean_sheets_p90 | J10: cleanSheet | L10: =IFERROR(_xlfn.XLOOKUP(J10,feature_catalog!A:A,feature_catalog!A:A),"") -> cleanSheet
A11: savedShotsFromInsideTheBox | B11: saves_inside_p90 | C11: vol | D11: Arrêts sur tirs depuis l'intérieur de la surface de réparation — sous-ensemble des saves sur les tirs les plus dangereux (zone de vérité). Indicateur du niveau de difficulté des arrêts réalisés. | E11: Alisson arrête une frappe à bout portant de Haaland à 6m = 1 savedShotFromInsideTheBox | F11: GK | G11: FALSE | H11: feat_saves_inside_p90 | I11: z_saves_inside_p90 | J11: savedShotsFromInsideTheBox | L11: =IFERROR(_xlfn.XLOOKUP(J11,feature_catalog!A:A,feature_catalog!A:A),"") -> savedShotsFromInsideTheBox
A12: savedShotsFromOutsideTheBox | B12: saves_outside_p90 | C12: vol | D12: Arrêts sur tirs depuis l'extérieur de la surface — saves sur frappes lointaines. Généralement plus prévisibles mais peuvent être déviées. Indicateur du volume de tirs lointains arrêtés. | E12: Alisson arrête une frappe de 25m de Salah qui allait dans le coin = 1 savedShotFromOutsideTheBox | F12: GK | G12: FALSE | H12: feat_saves_outside_p90 | I12: z_saves_outside_p90 | J12: savedShotsFromOutsideTheBox | L12: =IFERROR(_xlfn.XLOOKUP(J12,feature_catalog!A:A,feature_catalog!A:A),"") -> savedShotsFromOutsideTheBox
A13: crossesNotClaimed | B13: crosses_not_claimed_p90 | C13: vol | D13: Centres non interceptés par le gardien — ballon joué depuis les côtés vers la surface que le gardien n'a pas capté ni dégagé. Feature à inverser : plus ce nombre est élevé, moins le gardien contrôle sa surface. | E13: Un corner arrive dans la surface, Courtois ne sort pas et le ballon traîne = 1 crossNotClaimed | F13: GK | G13: TRUE | H13: feat_crosses_not_claimed_p90 | I13: z_crosses_not_claimed_p90 | J13: crossesNotClaimed | L13: =IFERROR(_xlfn.XLOOKUP(J13,feature_catalog!A:A,feature_catalog!A:A),"") -> crossesNotClaimed
A14: _penalty_save_pct | B14: penalty_save_pct | C14: pct | D14: % pénaltys arrêtés = penaltySave / penaltyFaced × 100. Mesure la performance du gardien sur penalty. Calculé uniquement pour les gardiens ayant fait face à au moins 1 pénalty saison. | E14: Alisson face à 5 pénaltys, en arrête 2 = 40% penalty_save_pct. Moyenne PL gardien ≈ 20-30% | F14: GK | G14: FALSE | H14: feat_penalty_save_pct | I14: z_penalty_save_pct | J14: _penalty_save_pct | K14: 2 | L14: =IFERROR(_xlfn.XLOOKUP(J14,feature_catalog!A:A,feature_catalog!A:A),"") -> _penalty_save_pct
A15: rating | B15: ss_rating | C15: raw | D15: Note SofaScore calculée algorithmiquement à partir de l'ensemble des actions de jeu pondérées par poste. Échelle 1-10, mise à jour après chaque match. Utilisée comme benchmark de validation des scores du modèle. | E15: De Bruyne : moyenne 7.3 sur la saison = excellent. Moyenne joueur ≈ 6.8. Gardien bonne saison ≈ 7.0-7.2 | F15: ALL | G15: FALSE | H15: feat_ss_rating | I15: z_ss_rating | J15: rating | L15: =IFERROR(_xlfn.XLOOKUP(J15,feature_catalog!A:A,feature_catalog!A:A),"") -> rating
A16: _save_pct | B16: save_pct | C16: pct | D16: Arrêts réalisés divisés par tirs cadrés adverses reçus. Ne tient pas compte de la difficulté des tirs (contrairement à PSxG). Un gardien face à une équipe qui tire beaucoup de loin aura mécaniquement un bon % même s'il n'est pas excellent. | E16: Alisson : 112 arrêts / 140 tirs cadrés = 80%. Valeur top gardien PL ≈ 72-78% | F16: GK | G16: FALSE | H16: feat_save_pct | I16: z_save_pct | J16: _save_pct | L16: =IFERROR(_xlfn.XLOOKUP(J16,feature_catalog!A:A,feature_catalog!A:A),"") -> _save_pct
A17: goalsConceded | B17: goals_conc_p90 | C17: vol | D17: Buts encaissés sur la saison. Feature à inverser : moins le gardien encaisse, mieux c'est. Corrélé à la qualité défensive collective — un gardien de grande équipe encaissera naturellement moins. | E17: Courtois encaisse 1 but par match en moyenne = 1 goal_conc_p90. Top gardien PL ≈ 0.8-1.0 | F17: GK | G17: TRUE | H17: feat_goals_conc_p90 | I17: z_goals_conc_p90 | J17: goalsConceded | L17: =IFERROR(_xlfn.XLOOKUP(J17,feature_catalog!A:A,feature_catalog!A:A),"") -> goalsConceded
A18: xGoalsConceded | B18: xg_conc_p90 | C18: vol | D18: xGoals concédés — somme des probabilités de but des tirs adverses reçus. Mesure la difficulté des arrêts du gardien indépendamment des résultats. Base du calcul de goalsPrevented. | E18: Ederson reçoit 5 tirs/match avec xGC cumulé = 1.2/match → équipe concède moins que prévu si réels buts < 1.2 | F18: GK | G18: TRUE | H18: feat_xg_conc_p90 | I18: z_xg_conc_p90 | J18: xGoalsConceded | L18: =IFERROR(_xlfn.XLOOKUP(J18,feature_catalog!A:A,feature_catalog!A:A),"")
A19: goalsPrevented | B19: goals_prevented_p90 | C19: vol | D19: Buts évités = arrêts réalisés moins xGoals concédés attendus. Mesure la surperformance du gardien par rapport aux attentes. Équivalent SofaScore du PSxG+/- de FBref. Positif = meilleur que prévu, négatif = moins bon. | E19: Ederson reçoit 45 tirs cadrés avec xGC=38.5, encaisse 34 buts → goalsPrevented = 38.5-34 = +4.5 (surperformance) | F19: GK | G19: FALSE | H19: feat_goals_prevented_p90 | I19: z_goals_prevented_p90 | J19: goalsPrevented | K19: 4 | L19: =IFERROR(_xlfn.XLOOKUP(J19,feature_catalog!A:A,feature_catalog!A:A),"") -> goalsPrevented
A20: penaltiesSaved | B20: pk_saved_p90 | C20: vol | D20: Pénaltys arrêtés en absolu (nb de penalties stoppés sur la saison). Comptabilise uniquement les arrêts directs, pas les tirs repoussés puis marqués sur le rebond. | E20: Alisson arrête 2 pénaltys sur la saison = 2 penaltiesSaved. Stat très rare — la plupart des gardiens → 0-1/saison | F20: GK | G20: FALSE | H20: feat_pk_saved_p90 | I20: z_pk_saved_p90 | J20: penaltiesSaved | L20: =IFERROR(_xlfn.XLOOKUP(J20,feature_catalog!A:A,feature_catalog!A:A),"")
A21: highClaims | B21: high_claims_p90 | C21: vol | D21: Captages hauts réussis — le gardien sort aériennement pour attraper ou dégager un centre ou corner en hauteur, en challengeant avec des attaquants adverses. Réussi = le gardien capture ou dégage proprement sans laisser la balle traîner. | E21: Alisson sort sur un corner, capte le ballon devant Lukaku qui challengeait = 1 high claim réussi. Alisson sort, perd le duel et le ballon traîne = 0 high claim réussi | F21: GK | G21: FALSE | H21: feat_high_claims_p90 | I21: z_high_claims_p90 | J21: highClaims | L21: =IFERROR(_xlfn.XLOOKUP(J21,feature_catalog!A:A,feature_catalog!A:A),"") -> highClaims
A22: runsOut | B22: runs_out_p90 | C22: vol | D22: Sorties physiques du gardien HORS de sa surface de réparation pour intervenir sur le ballon — couper une passe longue, contrer un dribbleur en un-contre-un, dégager un ballon avant l'attaquant. Le gardien doit franchir la ligne des 18m. | E22: Neuer sort à 30m de son but pour couper un ballon dans le dos de Boateng = 1 runOut. Neuer sort à la limite de sa surface = 0 runOut | F22: GK | G22: FALSE | H22: feat_runs_out_p90 | I22: z_runs_out_p90 | J22: runsOut | L22: =IFERROR(_xlfn.XLOOKUP(J22,feature_catalog!A:A,feature_catalog!A:A),"") -> runsOut
A23: successfulRunsOut | B23: runs_out_suc_p90 | C23: vol | D23: Sous-ensemble des sorties (runsOut) réussies — le gardien récupère proprement le ballon ou le dégage sans laisser de rebond dangereux. Indicateur de précision dans les sorties hors surface. | E23: Neuer sort à 25m et capte le ballon proprement = 1 successful runOut. Neuer sort, rate le ballon, attaquant passe à côté = runOut non réussi | F23: GK | G23: FALSE | H23: feat_runs_out_suc_p90 | I23: z_runs_out_suc_p90 | J23: successfulRunsOut | L23: =IFERROR(_xlfn.XLOOKUP(J23,feature_catalog!A:A,feature_catalog!A:A),"") -> successfulRunsOut
A24: punches | B24: punches_p90 | C24: vol | D24: Dégagements au poing — action du gardien qui repousse le ballon du poing plutôt que de le capter. Souvent utilisé sur les centres difficiles à contrôler en conditions de pression. | E24: Lloris ne peut pas capter un corner tendu et repousse du poing = 1 punch | F24: GK | G24: FALSE | H24: feat_punches_p90 | I24: z_punches_p90 | J24: punches | L24: =IFERROR(_xlfn.XLOOKUP(J24,feature_catalog!A:A,feature_catalog!A:A),"") -> punches
A25: totalKeeperSweeper | B25: gk_sweeper_p90 | C25: vol | D25: Actions sweeper du gardien = toutes les interventions où le gardien agit en dernier défenseur sur un ballon dangereux arrivant derrière sa défense. Plus large que runsOut — inclut les sorties DANS la surface sur ballons filtrés. runsOut ⊂ keeperSweeper. | E25: Ederson sort à 30m = runOut ET keeperSweeper. Ederson sort à 15m (dans sa surface) pour couper un ballon filtré = keeperSweeper mais PAS runOut | F25: GK | G25: FALSE | H25: feat_gk_sweeper_p90 | I25: z_gk_sweeper_p90 | J25: totalKeeperSweeper | L25: =IFERROR(_xlfn.XLOOKUP(J25,feature_catalog!A:A,feature_catalog!A:A),"")
A26: accurateKeeperSweeper | B26: gk_sweeper_acc_p90 | C26: vol | D26: Actions sweeper réussies — sous-ensemble des keeperSweeper où le gardien récupère ou dégage proprement le ballon arrivant derrière la défense. Indicateur de précision du jeu en sweeper keeper. | E26: Ederson sort en sweeper et capte proprement le ballon filtré = 1 accurate keeperSweeper. Ederson sort, manque le ballon = keeperSweeper non réussi | F26: GK | G26: FALSE | H26: feat_gk_sweeper_acc_p90 | I26: z_gk_sweeper_acc_p90 | J26: accurateKeeperSweeper | L26: =IFERROR(_xlfn.XLOOKUP(J26,feature_catalog!A:A,feature_catalog!A:A),"")
A27: accurateLongBallsPercentage | B27: gk_long_balls_pct | C27: pct | D27: % longues passes réussies du gardien — passes longues réussies / tentées. Indicateur clé du gardien relanceur ou sweeper keeper qui participe à la construction. | E27: Ederson joue 8 longues passes, 6 arrivent à un coéquipier = 75% gk_long_balls_pct | F27: GK | G27: FALSE | H27: feat_gk_long_balls_pct | I27: z_gk_long_balls_pct | J27: accurateLongBallsPercentage | L27: =IFERROR(_xlfn.XLOOKUP(J27,feature_catalog!A:A,feature_catalog!A:A),"") -> accurateLongBallsPercentage
A28: averageX | B28: avg_x | C28: raw | D28: Position X moyenne du joueur sur le terrain au moment de ses touches de balle, agrégée sur la saison via l'endpoint heatmap/overall SofaScore. X=0 = ligne de but propre, X=100 = ligne de but adverse. Calculé comme moyenne des coordonnées X de toutes les touches de la heatmap saison. | E28: Benzema saison faux-9 : avgX≈62 (milieu-haut). Haaland : avgX≈80 (très haut). Casemiro sentinelle : avgX≈35 (bas) | F28: ALL | G28: FALSE | H28: feat_avg_x | I28: z_avg_x | J28: averageX | L28: =IFERROR(_xlfn.XLOOKUP(J28,feature_catalog!A:A,feature_catalog!A:A),"") -> averageX
A29: averageY | B29: avg_y | C29: raw | D29: Position Y moyenne du joueur (axe latéral), agrégée sur la saison. Y=0 = ligne de touche gauche, Y=100 = ligne de touche droite, Y=50 = axe central. Utilisé pour distinguer ailier excentré (Y≈10 ou 90) d'un intérieur (Y≈30 ou 70). | E29: Trent Alexander-Arnold : avgY≈80 (côté droit collé). Modric : avgY≈50 (axe central). Salah ailier droit rentrant : avgY≈65 | F29: ALL | G29: FALSE | H29: feat_avg_y | I29: z_avg_y | J29: averageY | L29: =IFERROR(_xlfn.XLOOKUP(J29,feature_catalog!A:A,feature_catalog!A:A),"") -> averageY
A30: height | B30: height_cm | C30: raw | D30: Taille en cm déclarée sur le profil officiel Transfermarkt du joueur. Donnée statique, issue des fiches officielles clubs / fédérations. | E30: Virgil van Dijk : 193cm. Thibaut Courtois : 199cm. Seuil 'tour de contrôle' CB : ≥188cm | F30: CB|CF|GK | G30: FALSE | H30: feat_height_cm | I30: z_height_cm | J30: height | L30: =IFERROR(_xlfn.XLOOKUP(J30,feature_catalog!A:A,feature_catalog!A:A),"") -> height
A31: runs_out_pct | B31: runs_out_pct | C31: pct | D31: Sorties hors surface réussies / sorties tentées. runsOut = gardien franchit la ligne des 18m pour intervenir sur le ballon. successfulRunsOut = parmi ces sorties, celles où il obtient le ballon. | E31: Neuer : 18 runsOut, 16 successfulRunsOut → runs_out_pct = 88.9% | F31: GK | G31: False | H31: feat_runs_out_pct | I31: z_runs_out_pct
A32: high_claims_pct | B32: high_claims_pct | C32: pct | D32: Passes aériennes captées / (captées + ratées). highClaims = gardien sort et capte le ballon aérien. crossesNotClaimed = gardien sort pour capter un cross mais rate le ballon. Ratio de réussite sur les sorties aériennes tentées. | E32: Alisson : 28 highClaims, 3 crossesNotClaimed → high_claims_pct = 28/31 = 90.3% | F32: GK | G32: False | H32: feat_high_claims_pct | I32: z_high_claims_pct | K32: 2

Sheet gardien_libero
A1: source_column | B1: feature_name | C1: type | D1: description | E1: exemple | F1: relevant_roles | G1: inverted | H1: feat_col | I1: z_col | J1: source_column | K1: Pondération
A2: xGBuildup_us | B2: xgbuildup_p90 | C2: vol | D2: xGChain moins la contribution directe du tireur (xG) et du passeur décisif (xA). Mesure exclusivement les touches 'invisibles' en amont de la phase finale — la contribution à la construction profonde. | E2: Cancelo → De Bruyne → Haaland (but, xG=0.45). Cancelo : xGBuildup=0.45. De Bruyne : xGBuildup=0 (passeur déc. exclu). Haaland : xGBuildup=0 (tireur exclu) | F2: CM|DM|CB|FB|AM | G2: FALSE | H2: feat_xgbuildup_p90 | I2: z_xgbuildup_p90 | J2: xGBuildup_us | L2: =IFERROR(_xlfn.XLOOKUP(J2,feature_catalog!A:A,feature_catalog!A:A),"") -> xGBuildup_us
A3: accuratePasses | B3: acc_passes_p90 | C3: vol | D3: Nombre absolu de passes réussies sur la saison — passe qu'un coéquipier contrôle. Converti en per-90 pour la comparaison inter-joueurs. Exclut les corners, remises en jeu et dégagements gardien. | E3: Kroos : 85 passes réussies en 90min = 85 acc_passes pour ce match. Moyenne DM = 60-80 per-90 | F3: CM|DM|CB|AM | G3: FALSE | H3: feat_acc_passes_p90 | I3: z_acc_passes_p90 | J3: accuratePasses | L3: =IFERROR(_xlfn.XLOOKUP(J3,feature_catalog!A:A,feature_catalog!A:A),"") -> accuratePasses
A4: accuratePassesPercentage | B4: pass_acc_pct | C4: pct | D4: Passes réussies divisées par passes tentées. Une passe est réussie si un coéquipier la contrôle. Exclut les corners, remises en jeu, dégagements du gardien et centres (comptés séparément). | E4: Kroos : 85 passes réussies / 90 tentées = 94.4%. Moyenne DM Premier League ≈ 82% | F4: CM|DM|CB|FB|AM|GK | G4: FALSE | H4: feat_pass_acc_pct | I4: z_pass_acc_pct | J4: accuratePassesPercentage | K4: 1 | L4: =IFERROR(_xlfn.XLOOKUP(J4,feature_catalog!A:A,feature_catalog!A:A),"") -> accuratePassesPercentage
A5: accurateLongBalls | B5: long_balls_p90 | C5: vol | D5: Passes longues réussies — ballon joué en hauteur sur une distance significative (généralement >32m) récupéré par un coéquipier. Comptées en absolu per-90. | E5: Rúben Dias joue 8 longues passes dont 6 arrivent à un coéquipier = 6 long balls réussies | F5: CB|DM|GK|CM | G5: FALSE | H5: feat_long_balls_p90 | I5: z_long_balls_p90 | J5: accurateLongBalls | L5: =IFERROR(_xlfn.XLOOKUP(J5,feature_catalog!A:A,feature_catalog!A:A),"") -> accurateLongBalls
A6: accurateLongBallsPercentage | B6: long_balls_pct | C6: pct | D6: Passes longues réussies sur passes longues tentées. Une passe longue est définie par Opta comme un ballon joué en hauteur sur une distance significative (généralement >32m). Indicateur clé des CBs relanceurs et gardiens modernes. | E6: Rúben Dias joue 8 longues passes, 6 arrivent à un coéquipier = 75% long balls | F6: CB|DM|GK|CM | G6: FALSE | H6: feat_long_balls_pct | I6: z_long_balls_pct | J6: accurateLongBallsPercentage | K6: 1 | L6: =IFERROR(_xlfn.XLOOKUP(J6,feature_catalog!A:A,feature_catalog!A:A),"") -> accurateLongBallsPercentage
A7: touches | B7: touches_p90 | C7: vol | D7: Somme de tous les événements où le joueur touche le ballon — passe, tir, contrôle, dégagement, etc. Si un joueur contrôle puis passe, c'est 1 touche (l'action complète), pas 2. | E7: Iniesta reçoit, contrôle et passe en une action fluide = 1 touch. Un défenseur qui dévie involontairement un tir = 1 touch | F7: CF|CM|DM|AM|W | G7: FALSE | H7: feat_touches_p90 | I7: z_touches_p90 | J7: touches | L7: =IFERROR(_xlfn.XLOOKUP(J7,feature_catalog!A:A,feature_catalog!A:A),"") -> touches
A8: errorLeadToGoal | B8: errors_goal_p90 | C8: vol | D8: Erreur individuelle d'un joueur menant DIRECTEMENT à un but encaissé. L'erreur doit être la cause directe sans phase de jeu intermédiaire. Très rare — 0 à 2 occurrences par saison pour la plupart des joueurs. | E8: Maguire perd le ballon dans sa propre surface, l'adversaire marque immédiatement = 1 errorLeadToGoal. Feature à inverser | F8: CD|GK|FB | G8: TRUE | H8: feat_errors_goal_p90 | I8: z_errors_goal_p90 | J8: errorLeadToGoal | L8: =IFERROR(_xlfn.XLOOKUP(J8,feature_catalog!A:A,feature_catalog!A:A),"") -> errorLeadToGoal
A9: errorLeadToShot | B9: errors_shot_p90 | C9: vol | D9: Erreur menant DIRECTEMENT à un tir adverse, but ou non. Sur-ensemble de errorLeadToGoal — chaque errorLeadToGoal est aussi un errorLeadToShot mais pas l'inverse. Légèrement plus fréquent (2-6/saison). | E9: Stones glisse et offre le ballon à Salah qui tire (gardien arrête) = 1 errorLeadToShot mais pas errorLeadToGoal | F9: CD|GK|FB | G9: TRUE | H9: feat_errors_shot_p90 | I9: z_errors_shot_p90 | J9: errorLeadToShot | K9: 3 | L9: =IFERROR(_xlfn.XLOOKUP(J9,feature_catalog!A:A,feature_catalog!A:A),"") -> errorLeadToShot
A10: headedClearances | B10: headed_clear_p90 | C10: vol | D10: Sous-ensemble des clearances : dégagements effectués de la tête uniquement. Indicateur de domination aérienne défensive dans la surface propre. | E10: Dias dégage un corner adverse de la tête = 1 headed clearance | F10: CB|GK | G10: FALSE | H10: feat_headed_clear_p90 | I10: z_headed_clear_p90 | J10: headedClearances | L10: =IFERROR(_xlfn.XLOOKUP(J10,feature_catalog!A:A,feature_catalog!A:A),"")
A11: saves | B11: saves_p90 | C11: vol | D11: Arrêts réalisés — tirs cadrés adverses stoppés par le gardien. Comptés uniquement sur les tirs qui auraient constitué un but sans l'intervention. Corrélé au volume de tirs adverses reçus. | E11: Alisson arrête un tir de Salah au premier poteau = 1 save. Alisson dévie un tir qui allait à côté = 0 save (pas cadré) | F11: GK | G11: FALSE | H11: feat_saves_p90 | I11: z_saves_p90 | J11: saves | L11: =IFERROR(_xlfn.XLOOKUP(J11,feature_catalog!A:A,feature_catalog!A:A),"") -> saves
A12: cleanSheet | B12: clean_sheets_p90 | C12: vol | D12: Match sans but encaissé — gardien ayant tenu sa cage à zéro pour la totalité du match joué. Per-90 utilisé comme proportion de matchs à zéro. Corrélé à la qualité défensive collective. | E12: Ederson joue 90min sans encaisser = 1 cleanSheet. Ederson sort à la 80e (0-0), remplaçant encaisse = pas de cleanSheet | F12: GK | G12: FALSE | H12: feat_clean_sheets_p90 | I12: z_clean_sheets_p90 | J12: cleanSheet | L12: =IFERROR(_xlfn.XLOOKUP(J12,feature_catalog!A:A,feature_catalog!A:A),"") -> cleanSheet
A13: savedShotsFromInsideTheBox | B13: saves_inside_p90 | C13: vol | D13: Arrêts sur tirs depuis l'intérieur de la surface de réparation — sous-ensemble des saves sur les tirs les plus dangereux (zone de vérité). Indicateur du niveau de difficulté des arrêts réalisés. | E13: Alisson arrête une frappe à bout portant de Haaland à 6m = 1 savedShotFromInsideTheBox | F13: GK | G13: FALSE | H13: feat_saves_inside_p90 | I13: z_saves_inside_p90 | J13: savedShotsFromInsideTheBox | L13: =IFERROR(_xlfn.XLOOKUP(J13,feature_catalog!A:A,feature_catalog!A:A),"") -> savedShotsFromInsideTheBox
A14: savedShotsFromOutsideTheBox | B14: saves_outside_p90 | C14: vol | D14: Arrêts sur tirs depuis l'extérieur de la surface — saves sur frappes lointaines. Généralement plus prévisibles mais peuvent être déviées. Indicateur du volume de tirs lointains arrêtés. | E14: Alisson arrête une frappe de 25m de Salah qui allait dans le coin = 1 savedShotFromOutsideTheBox | F14: GK | G14: FALSE | H14: feat_saves_outside_p90 | I14: z_saves_outside_p90 | J14: savedShotsFromOutsideTheBox | L14: =IFERROR(_xlfn.XLOOKUP(J14,feature_catalog!A:A,feature_catalog!A:A),"") -> savedShotsFromOutsideTheBox
A15: crossesNotClaimed | B15: crosses_not_claimed_p90 | C15: vol | D15: Centres non interceptés par le gardien — ballon joué depuis les côtés vers la surface que le gardien n'a pas capté ni dégagé. Feature à inverser : plus ce nombre est élevé, moins le gardien contrôle sa surface. | E15: Un corner arrive dans la surface, Courtois ne sort pas et le ballon traîne = 1 crossNotClaimed | F15: GK | G15: TRUE | H15: feat_crosses_not_claimed_p90 | I15: z_crosses_not_claimed_p90 | J15: crossesNotClaimed | L15: =IFERROR(_xlfn.XLOOKUP(J15,feature_catalog!A:A,feature_catalog!A:A),"") -> crossesNotClaimed
A16: _penalty_save_pct | B16: penalty_save_pct | C16: pct | D16: % pénaltys arrêtés = penaltySave / penaltyFaced × 100. Mesure la performance du gardien sur penalty. Calculé uniquement pour les gardiens ayant fait face à au moins 1 pénalty saison. | E16: Alisson face à 5 pénaltys, en arrête 2 = 40% penalty_save_pct. Moyenne PL gardien ≈ 20-30% | F16: GK | G16: FALSE | H16: feat_penalty_save_pct | I16: z_penalty_save_pct | J16: _penalty_save_pct | K16: 1.5 | L16: =IFERROR(_xlfn.XLOOKUP(J16,feature_catalog!A:A,feature_catalog!A:A),"") -> _penalty_save_pct
A17: rating | B17: ss_rating | C17: raw | D17: Note SofaScore calculée algorithmiquement à partir de l'ensemble des actions de jeu pondérées par poste. Échelle 1-10, mise à jour après chaque match. Utilisée comme benchmark de validation des scores du modèle. | E17: De Bruyne : moyenne 7.3 sur la saison = excellent. Moyenne joueur ≈ 6.8. Gardien bonne saison ≈ 7.0-7.2 | F17: ALL | G17: FALSE | H17: feat_ss_rating | I17: z_ss_rating | J17: rating | L17: =IFERROR(_xlfn.XLOOKUP(J17,feature_catalog!A:A,feature_catalog!A:A),"") -> rating
A18: _save_pct | B18: save_pct | C18: pct | D18: Arrêts réalisés divisés par tirs cadrés adverses reçus. Ne tient pas compte de la difficulté des tirs (contrairement à PSxG). Un gardien face à une équipe qui tire beaucoup de loin aura mécaniquement un bon % même s'il n'est pas excellent. | E18: Alisson : 112 arrêts / 140 tirs cadrés = 80%. Valeur top gardien PL ≈ 72-78% | F18: GK | G18: FALSE | H18: feat_save_pct | I18: z_save_pct | J18: _save_pct | L18: =IFERROR(_xlfn.XLOOKUP(J18,feature_catalog!A:A,feature_catalog!A:A),"") -> _save_pct
A19: goalsConceded | B19: goals_conc_p90 | C19: vol | D19: Buts encaissés sur la saison. Feature à inverser : moins le gardien encaisse, mieux c'est. Corrélé à la qualité défensive collective — un gardien de grande équipe encaissera naturellement moins. | E19: Courtois encaisse 1 but par match en moyenne = 1 goal_conc_p90. Top gardien PL ≈ 0.8-1.0 | F19: GK | G19: TRUE | H19: feat_goals_conc_p90 | I19: z_goals_conc_p90 | J19: goalsConceded | L19: =IFERROR(_xlfn.XLOOKUP(J19,feature_catalog!A:A,feature_catalog!A:A),"") -> goalsConceded
A20: xGoalsConceded | B20: xg_conc_p90 | C20: vol | D20: xGoals concédés — somme des probabilités de but des tirs adverses reçus. Mesure la difficulté des arrêts du gardien indépendamment des résultats. Base du calcul de goalsPrevented. | E20: Ederson reçoit 5 tirs/match avec xGC cumulé = 1.2/match → équipe concède moins que prévu si réels buts < 1.2 | F20: GK | G20: TRUE | H20: feat_xg_conc_p90 | I20: z_xg_conc_p90 | J20: xGoalsConceded | L20: =IFERROR(_xlfn.XLOOKUP(J20,feature_catalog!A:A,feature_catalog!A:A),"")
A21: goalsPrevented | B21: goals_prevented_p90 | C21: vol | D21: Buts évités = arrêts réalisés moins xGoals concédés attendus. Mesure la surperformance du gardien par rapport aux attentes. Équivalent SofaScore du PSxG+/- de FBref. Positif = meilleur que prévu, négatif = moins bon. | E21: Ederson reçoit 45 tirs cadrés avec xGC=38.5, encaisse 34 buts → goalsPrevented = 38.5-34 = +4.5 (surperformance) | F21: GK | G21: FALSE | H21: feat_goals_prevented_p90 | I21: z_goals_prevented_p90 | J21: goalsPrevented | K21: 4 | L21: =IFERROR(_xlfn.XLOOKUP(J21,feature_catalog!A:A,feature_catalog!A:A),"") -> goalsPrevented
A22: penaltiesSaved | B22: pk_saved_p90 | C22: vol | D22: Pénaltys arrêtés en absolu (nb de penalties stoppés sur la saison). Comptabilise uniquement les arrêts directs, pas les tirs repoussés puis marqués sur le rebond. | E22: Alisson arrête 2 pénaltys sur la saison = 2 penaltiesSaved. Stat très rare — la plupart des gardiens → 0-1/saison | F22: GK | G22: FALSE | H22: feat_pk_saved_p90 | I22: z_pk_saved_p90 | J22: penaltiesSaved | L22: =IFERROR(_xlfn.XLOOKUP(J22,feature_catalog!A:A,feature_catalog!A:A),"")
A23: highClaims | B23: high_claims_p90 | C23: vol | D23: Captages hauts réussis — le gardien sort aériennement pour attraper ou dégager un centre ou corner en hauteur, en challengeant avec des attaquants adverses. Réussi = le gardien capture ou dégage proprement sans laisser la balle traîner. | E23: Alisson sort sur un corner, capte le ballon devant Lukaku qui challengeait = 1 high claim réussi. Alisson sort, perd le duel et le ballon traîne = 0 high claim réussi | F23: GK | G23: FALSE | H23: feat_high_claims_p90 | I23: z_high_claims_p90 | J23: highClaims | L23: =IFERROR(_xlfn.XLOOKUP(J23,feature_catalog!A:A,feature_catalog!A:A),"") -> highClaims
A24: runsOut | B24: runs_out_p90 | C24: vol | D24: Sorties physiques du gardien HORS de sa surface de réparation pour intervenir sur le ballon — couper une passe longue, contrer un dribbleur en un-contre-un, dégager un ballon avant l'attaquant. Le gardien doit franchir la ligne des 18m. | E24: Neuer sort à 30m de son but pour couper un ballon dans le dos de Boateng = 1 runOut. Neuer sort à la limite de sa surface = 0 runOut | F24: GK | G24: FALSE | H24: feat_runs_out_p90 | I24: z_runs_out_p90 | J24: runsOut | K24: 1 | L24: =IFERROR(_xlfn.XLOOKUP(J24,feature_catalog!A:A,feature_catalog!A:A),"") -> runsOut
A25: successfulRunsOut | B25: runs_out_suc_p90 | C25: vol | D25: Sous-ensemble des sorties (runsOut) réussies — le gardien récupère proprement le ballon ou le dégage sans laisser de rebond dangereux. Indicateur de précision dans les sorties hors surface. | E25: Neuer sort à 25m et capte le ballon proprement = 1 successful runOut. Neuer sort, rate le ballon, attaquant passe à côté = runOut non réussi | F25: GK | G25: FALSE | H25: feat_runs_out_suc_p90 | I25: z_runs_out_suc_p90 | J25: successfulRunsOut | L25: =IFERROR(_xlfn.XLOOKUP(J25,feature_catalog!A:A,feature_catalog!A:A),"") -> successfulRunsOut
A26: totalKeeperSweeper | B26: gk_sweeper_p90 | C26: vol | D26: Actions sweeper du gardien = toutes les interventions où le gardien agit en dernier défenseur sur un ballon dangereux arrivant derrière sa défense. Plus large que runsOut — inclut les sorties DANS la surface sur ballons filtrés. runsOut ⊂ keeperSweeper. | E26: Ederson sort à 30m = runOut ET keeperSweeper. Ederson sort à 15m (dans sa surface) pour couper un ballon filtré = keeperSweeper mais PAS runOut | F26: GK | G26: FALSE | H26: feat_gk_sweeper_p90 | I26: z_gk_sweeper_p90 | J26: totalKeeperSweeper | L26: =IFERROR(_xlfn.XLOOKUP(J26,feature_catalog!A:A,feature_catalog!A:A),"")
A27: accurateKeeperSweeper | B27: gk_sweeper_acc_p90 | C27: vol | D27: Actions sweeper réussies — sous-ensemble des keeperSweeper où le gardien récupère ou dégage proprement le ballon arrivant derrière la défense. Indicateur de précision du jeu en sweeper keeper. | E27: Ederson sort en sweeper et capte proprement le ballon filtré = 1 accurate keeperSweeper. Ederson sort, manque le ballon = keeperSweeper non réussi | F27: GK | G27: FALSE | H27: feat_gk_sweeper_acc_p90 | I27: z_gk_sweeper_acc_p90 | J27: accurateKeeperSweeper | L27: =IFERROR(_xlfn.XLOOKUP(J27,feature_catalog!A:A,feature_catalog!A:A),"")
A28: accurateLongBallsPercentage | B28: gk_long_balls_pct | C28: pct | D28: % longues passes réussies du gardien — passes longues réussies / tentées. Indicateur clé du gardien relanceur ou sweeper keeper qui participe à la construction. | E28: Ederson joue 8 longues passes, 6 arrivent à un coéquipier = 75% gk_long_balls_pct | F28: GK | G28: FALSE | H28: feat_gk_long_balls_pct | I28: z_gk_long_balls_pct | J28: accurateLongBallsPercentage | L28: =IFERROR(_xlfn.XLOOKUP(J28,feature_catalog!A:A,feature_catalog!A:A),"") -> accurateLongBallsPercentage
A29: averageX | B29: avg_x | C29: raw | D29: Position X moyenne du joueur sur le terrain au moment de ses touches de balle, agrégée sur la saison via l'endpoint heatmap/overall SofaScore. X=0 = ligne de but propre, X=100 = ligne de but adverse. Calculé comme moyenne des coordonnées X de toutes les touches de la heatmap saison. | E29: Benzema saison faux-9 : avgX≈62 (milieu-haut). Haaland : avgX≈80 (très haut). Casemiro sentinelle : avgX≈35 (bas) | F29: ALL | G29: FALSE | H29: feat_avg_x | I29: z_avg_x | J29: averageX | L29: =IFERROR(_xlfn.XLOOKUP(J29,feature_catalog!A:A,feature_catalog!A:A),"") -> averageX
A30: averageY | B30: avg_y | C30: raw | D30: Position Y moyenne du joueur (axe latéral), agrégée sur la saison. Y=0 = ligne de touche gauche, Y=100 = ligne de touche droite, Y=50 = axe central. Utilisé pour distinguer ailier excentré (Y≈10 ou 90) d'un intérieur (Y≈30 ou 70). | E30: Trent Alexander-Arnold : avgY≈80 (côté droit collé). Modric : avgY≈50 (axe central). Salah ailier droit rentrant : avgY≈65 | F30: ALL | G30: FALSE | H30: feat_avg_y | I30: z_avg_y | J30: averageY | L30: =IFERROR(_xlfn.XLOOKUP(J30,feature_catalog!A:A,feature_catalog!A:A),"") -> averageY
A31: height | B31: height_cm | C31: raw | D31: Taille en cm déclarée sur le profil officiel Transfermarkt du joueur. Donnée statique, issue des fiches officielles clubs / fédérations. | E31: Virgil van Dijk : 193cm. Thibaut Courtois : 199cm. Seuil 'tour de contrôle' CB : ≥188cm | F31: CB|CF|GK | G31: FALSE | H31: feat_height_cm | I31: z_height_cm | J31: height | L31: =IFERROR(_xlfn.XLOOKUP(J31,feature_catalog!A:A,feature_catalog!A:A),"") -> height
A32: runs_out_pct | B32: runs_out_pct | C32: pct | D32: Sorties hors surface réussies / sorties tentées. runsOut = gardien franchit la ligne des 18m pour intervenir sur le ballon. successfulRunsOut = parmi ces sorties, celles où il obtient le ballon. | E32: Neuer : 18 runsOut, 16 successfulRunsOut → runs_out_pct = 88.9% | F32: GK | G32: False | H32: feat_runs_out_pct | I32: z_runs_out_pct | J32: runs_out_pct | K32: 2 | L32: =IFERROR(_xlfn.XLOOKUP(J32,feature_catalog!A:A,feature_catalog!A:A),"") -> runs_out_pct
A33: high_claims_pct | B33: high_claims_pct | C33: pct | D33: Passes aériennes captées / (captées + ratées). highClaims = gardien sort et capte le ballon aérien. crossesNotClaimed = gardien sort pour capter un cross mais rate le ballon. Ratio de réussite sur les sorties aériennes tentées. | E33: Alisson : 28 highClaims, 3 crossesNotClaimed → high_claims_pct = 28/31 = 90.3% | F33: GK | G33: False | H33: feat_high_claims_pct | I33: z_high_claims_pct | J33: high_claims_pct | K33: 1.5 | L33: =IFERROR(_xlfn.XLOOKUP(J33,feature_catalog!A:A,feature_catalog!A:A),"") -> high_claims_pct

Sheet gardien_relanceur
A1: source_column | B1: feature_name | C1: type | D1: description | E1: exemple | F1: relevant_roles | G1: inverted | H1: feat_col | I1: z_col | J1: source_column | K1: Pondération
A2: xGChain_us | B2: xgchain_p90 | C2: vol | D2: Somme des xG de toutes les occasions auxquelles le joueur a participé dans la séquence de jeu, qu'il ait tiré, passé, ou simplement touché le ballon à n'importe quel moment de l'action. Très inclusif. | E2: Modric touche le ballon 3 passes avant le tir de Benzema (xG=0.25) → Modric reçoit 0.25 dans son xGChain | F2: CF|W|AM|CM|DM|FB | G2: False | H2: feat_xgchain_p90 | I2: z_xgchain_p90 | J2: xGChain_us | K2: 2 | L2: =IFERROR(_xlfn.XLOOKUP(J2,feature_catalog!A:A,feature_catalog!A:A),"") -> xGChain_us
A3: expectedAssists | B3: xa_p90 | C3: vol | D3: xG de l'occasion créée par la passe, calculé au moment où le receveur tire. Mesure la qualité des passes menant à un tir, quel que soit le résultat du tir. Une passe vers un xG=0.5 vaut xA=0.5 même si le tir est raté. | E3: Passe dans la surface pour tir à bout portant (xG=0.45) = xA=0.45 pour le passeur. Passe vers une frappe lointaine (xG=0.03) = xA=0.03 | F3: W|AM|CM|CF|FB | G3: FALSE | H3: feat_xa_p90 | I3: z_xa_p90 | J3: expectedAssists | L3: =IFERROR(_xlfn.XLOOKUP(J3,feature_catalog!A:A,feature_catalog!A:A),"") -> expectedAssists
A4: keyPasses | B4: key_passes_p90 | C4: vol | D4: Passe menant directement à une tentative de but de l'équipe, sans être une passe décisive officielle (le tir ne se transforme pas en but). Critère : la passe doit être la dernière avant le tir. | E4: Ødegaard joue une passe à Saka qui tire, gardien arrête = 1 key pass pour Ødegaard. Si Saka marque = assist, pas key pass | F4: AM|CM|W|CF|FB | G4: FALSE | H4: feat_key_passes_p90 | I4: z_key_passes_p90 | J4: keyPasses | L4: =IFERROR(_xlfn.XLOOKUP(J4,feature_catalog!A:A,feature_catalog!A:A),"") -> keyPasses
A5: accuratePasses | B5: acc_passes_p90 | C5: vol | D5: Nombre absolu de passes réussies sur la saison — passe qu'un coéquipier contrôle. Converti en per-90 pour la comparaison inter-joueurs. Exclut les corners, remises en jeu et dégagements gardien. | E5: Kroos : 85 passes réussies en 90min = 85 acc_passes pour ce match. Moyenne DM = 60-80 per-90 | F5: CM|DM|CB|AM | G5: FALSE | H5: feat_acc_passes_p90 | I5: z_acc_passes_p90 | J5: accuratePasses | L5: =IFERROR(_xlfn.XLOOKUP(J5,feature_catalog!A:A,feature_catalog!A:A),"") -> accuratePasses
A6: accuratePassesPercentage | B6: pass_acc_pct | C6: pct | D6: Passes réussies divisées par passes tentées. Une passe est réussie si un coéquipier la contrôle. Exclut les corners, remises en jeu, dégagements du gardien et centres (comptés séparément). | E6: Kroos : 85 passes réussies / 90 tentées = 94.4%. Moyenne DM Premier League ≈ 82% | F6: CM|DM|CB|FB|AM|GK | G6: FALSE | H6: feat_pass_acc_pct | I6: z_pass_acc_pct | J6: accuratePassesPercentage | K6: 2 | L6: =IFERROR(_xlfn.XLOOKUP(J6,feature_catalog!A:A,feature_catalog!A:A),"") -> accuratePassesPercentage
A7: accurateLongBalls | B7: long_balls_p90 | C7: vol | D7: Passes longues réussies — ballon joué en hauteur sur une distance significative (généralement >32m) récupéré par un coéquipier. Comptées en absolu per-90. | E7: Rúben Dias joue 8 longues passes dont 6 arrivent à un coéquipier = 6 long balls réussies | F7: CB|DM|GK|CM | G7: FALSE | H7: feat_long_balls_p90 | I7: z_long_balls_p90 | J7: accurateLongBalls | L7: =IFERROR(_xlfn.XLOOKUP(J7,feature_catalog!A:A,feature_catalog!A:A),"") -> accurateLongBalls
A8: accurateLongBallsPercentage | B8: long_balls_pct | C8: pct | D8: Passes longues réussies sur passes longues tentées. Une passe longue est définie par Opta comme un ballon joué en hauteur sur une distance significative (généralement >32m). Indicateur clé des CBs relanceurs et gardiens modernes. | E8: Rúben Dias joue 8 longues passes, 6 arrivent à un coéquipier = 75% long balls | F8: CB|DM|GK|CM | G8: FALSE | H8: feat_long_balls_pct | I8: z_long_balls_pct | J8: accurateLongBallsPercentage | K8: 2 | L8: =IFERROR(_xlfn.XLOOKUP(J8,feature_catalog!A:A,feature_catalog!A:A),"") -> accurateLongBallsPercentage
A9: possessionLost | B9: poss_lost_p90 | C9: vol | D9: Nombre de fois où le joueur perd la possession — tacle adverse réussi sur lui, mauvais contrôle, passe ratée dans les pieds adverses, interception subie. Comptabilisé uniquement quand la possession change d'équipe suite à l'action du joueur. | E9: Griezmann reçoit, adverse le tacklé et récupère le ballon = 1 possession lost pour Griezmann | F9: CF|W|CM|DM|CB | G9: TRUE | H9: feat_poss_lost_p90 | I9: z_poss_lost_p90 | J9: possessionLost | K9: 2 | L9: =IFERROR(_xlfn.XLOOKUP(J9,feature_catalog!A:A,feature_catalog!A:A),"") -> possessionLost
A10: errorLeadToGoal | B10: errors_goal_p90 | C10: vol | D10: Erreur individuelle d'un joueur menant DIRECTEMENT à un but encaissé. L'erreur doit être la cause directe sans phase de jeu intermédiaire. Très rare — 0 à 2 occurrences par saison pour la plupart des joueurs. | E10: Maguire perd le ballon dans sa propre surface, l'adversaire marque immédiatement = 1 errorLeadToGoal. Feature à inverser | F10: CD|GK|FB | G10: TRUE | H10: feat_errors_goal_p90 | I10: z_errors_goal_p90 | J10: errorLeadToGoal | L10: =IFERROR(_xlfn.XLOOKUP(J10,feature_catalog!A:A,feature_catalog!A:A),"") -> errorLeadToGoal
A11: errorLeadToShot | B11: errors_shot_p90 | C11: vol | D11: Erreur menant DIRECTEMENT à un tir adverse, but ou non. Sur-ensemble de errorLeadToGoal — chaque errorLeadToGoal est aussi un errorLeadToShot mais pas l'inverse. Légèrement plus fréquent (2-6/saison). | E11: Stones glisse et offre le ballon à Salah qui tire (gardien arrête) = 1 errorLeadToShot mais pas errorLeadToGoal | F11: CD|GK|FB | G11: TRUE | H11: feat_errors_shot_p90 | I11: z_errors_shot_p90 | J11: errorLeadToShot | K11: 1 | L11: =IFERROR(_xlfn.XLOOKUP(J11,feature_catalog!A:A,feature_catalog!A:A),"") -> errorLeadToShot
A12: headedClearances | B12: headed_clear_p90 | C12: vol | D12: Sous-ensemble des clearances : dégagements effectués de la tête uniquement. Indicateur de domination aérienne défensive dans la surface propre. | E12: Dias dégage un corner adverse de la tête = 1 headed clearance | F12: CB|GK | G12: FALSE | H12: feat_headed_clear_p90 | I12: z_headed_clear_p90 | J12: headedClearances | L12: =IFERROR(_xlfn.XLOOKUP(J12,feature_catalog!A:A,feature_catalog!A:A),"")
A13: saves | B13: saves_p90 | C13: vol | D13: Arrêts réalisés — tirs cadrés adverses stoppés par le gardien. Comptés uniquement sur les tirs qui auraient constitué un but sans l'intervention. Corrélé au volume de tirs adverses reçus. | E13: Alisson arrête un tir de Salah au premier poteau = 1 save. Alisson dévie un tir qui allait à côté = 0 save (pas cadré) | F13: GK | G13: FALSE | H13: feat_saves_p90 | I13: z_saves_p90 | J13: saves | L13: =IFERROR(_xlfn.XLOOKUP(J13,feature_catalog!A:A,feature_catalog!A:A),"") -> saves
A14: cleanSheet | B14: clean_sheets_p90 | C14: vol | D14: Match sans but encaissé — gardien ayant tenu sa cage à zéro pour la totalité du match joué. Per-90 utilisé comme proportion de matchs à zéro. Corrélé à la qualité défensive collective. | E14: Ederson joue 90min sans encaisser = 1 cleanSheet. Ederson sort à la 80e (0-0), remplaçant encaisse = pas de cleanSheet | F14: GK | G14: FALSE | H14: feat_clean_sheets_p90 | I14: z_clean_sheets_p90 | J14: cleanSheet | L14: =IFERROR(_xlfn.XLOOKUP(J14,feature_catalog!A:A,feature_catalog!A:A),"") -> cleanSheet
A15: savedShotsFromInsideTheBox | B15: saves_inside_p90 | C15: vol | D15: Arrêts sur tirs depuis l'intérieur de la surface de réparation — sous-ensemble des saves sur les tirs les plus dangereux (zone de vérité). Indicateur du niveau de difficulté des arrêts réalisés. | E15: Alisson arrête une frappe à bout portant de Haaland à 6m = 1 savedShotFromInsideTheBox | F15: GK | G15: FALSE | H15: feat_saves_inside_p90 | I15: z_saves_inside_p90 | J15: savedShotsFromInsideTheBox | L15: =IFERROR(_xlfn.XLOOKUP(J15,feature_catalog!A:A,feature_catalog!A:A),"") -> savedShotsFromInsideTheBox
A16: savedShotsFromOutsideTheBox | B16: saves_outside_p90 | C16: vol | D16: Arrêts sur tirs depuis l'extérieur de la surface — saves sur frappes lointaines. Généralement plus prévisibles mais peuvent être déviées. Indicateur du volume de tirs lointains arrêtés. | E16: Alisson arrête une frappe de 25m de Salah qui allait dans le coin = 1 savedShotFromOutsideTheBox | F16: GK | G16: FALSE | H16: feat_saves_outside_p90 | I16: z_saves_outside_p90 | J16: savedShotsFromOutsideTheBox | L16: =IFERROR(_xlfn.XLOOKUP(J16,feature_catalog!A:A,feature_catalog!A:A),"") -> savedShotsFromOutsideTheBox
A17: crossesNotClaimed | B17: crosses_not_claimed_p90 | C17: vol | D17: Centres non interceptés par le gardien — ballon joué depuis les côtés vers la surface que le gardien n'a pas capté ni dégagé. Feature à inverser : plus ce nombre est élevé, moins le gardien contrôle sa surface. | E17: Un corner arrive dans la surface, Courtois ne sort pas et le ballon traîne = 1 crossNotClaimed | F17: GK | G17: TRUE | H17: feat_crosses_not_claimed_p90 | I17: z_crosses_not_claimed_p90 | J17: crossesNotClaimed | L17: =IFERROR(_xlfn.XLOOKUP(J17,feature_catalog!A:A,feature_catalog!A:A),"") -> crossesNotClaimed
A18: _penalty_save_pct | B18: penalty_save_pct | C18: pct | D18: % pénaltys arrêtés = penaltySave / penaltyFaced × 100. Mesure la performance du gardien sur penalty. Calculé uniquement pour les gardiens ayant fait face à au moins 1 pénalty saison. | E18: Alisson face à 5 pénaltys, en arrête 2 = 40% penalty_save_pct. Moyenne PL gardien ≈ 20-30% | F18: GK | G18: FALSE | H18: feat_penalty_save_pct | I18: z_penalty_save_pct | J18: _penalty_save_pct | K18: 1.5 | L18: =IFERROR(_xlfn.XLOOKUP(J18,feature_catalog!A:A,feature_catalog!A:A),"") -> _penalty_save_pct
A19: rating | B19: ss_rating | C19: raw | D19: Note SofaScore calculée algorithmiquement à partir de l'ensemble des actions de jeu pondérées par poste. Échelle 1-10, mise à jour après chaque match. Utilisée comme benchmark de validation des scores du modèle. | E19: De Bruyne : moyenne 7.3 sur la saison = excellent. Moyenne joueur ≈ 6.8. Gardien bonne saison ≈ 7.0-7.2 | F19: ALL | G19: FALSE | H19: feat_ss_rating | I19: z_ss_rating | J19: rating | L19: =IFERROR(_xlfn.XLOOKUP(J19,feature_catalog!A:A,feature_catalog!A:A),"") -> rating
A20: _save_pct | B20: save_pct | C20: pct | D20: Arrêts réalisés divisés par tirs cadrés adverses reçus. Ne tient pas compte de la difficulté des tirs (contrairement à PSxG). Un gardien face à une équipe qui tire beaucoup de loin aura mécaniquement un bon % même s'il n'est pas excellent. | E20: Alisson : 112 arrêts / 140 tirs cadrés = 80%. Valeur top gardien PL ≈ 72-78% | F20: GK | G20: FALSE | H20: feat_save_pct | I20: z_save_pct | J20: _save_pct | L20: =IFERROR(_xlfn.XLOOKUP(J20,feature_catalog!A:A,feature_catalog!A:A),"") -> _save_pct
A21: goalsConceded | B21: goals_conc_p90 | C21: vol | D21: Buts encaissés sur la saison. Feature à inverser : moins le gardien encaisse, mieux c'est. Corrélé à la qualité défensive collective — un gardien de grande équipe encaissera naturellement moins. | E21: Courtois encaisse 1 but par match en moyenne = 1 goal_conc_p90. Top gardien PL ≈ 0.8-1.0 | F21: GK | G21: TRUE | H21: feat_goals_conc_p90 | I21: z_goals_conc_p90 | J21: goalsConceded | L21: =IFERROR(_xlfn.XLOOKUP(J21,feature_catalog!A:A,feature_catalog!A:A),"") -> goalsConceded
A22: xGoalsConceded | B22: xg_conc_p90 | C22: vol | D22: xGoals concédés — somme des probabilités de but des tirs adverses reçus. Mesure la difficulté des arrêts du gardien indépendamment des résultats. Base du calcul de goalsPrevented. | E22: Ederson reçoit 5 tirs/match avec xGC cumulé = 1.2/match → équipe concède moins que prévu si réels buts < 1.2 | F22: GK | G22: TRUE | H22: feat_xg_conc_p90 | I22: z_xg_conc_p90 | J22: xGoalsConceded | L22: =IFERROR(_xlfn.XLOOKUP(J22,feature_catalog!A:A,feature_catalog!A:A),"")
A23: goalsPrevented | B23: goals_prevented_p90 | C23: vol | D23: Buts évités = arrêts réalisés moins xGoals concédés attendus. Mesure la surperformance du gardien par rapport aux attentes. Équivalent SofaScore du PSxG+/- de FBref. Positif = meilleur que prévu, négatif = moins bon. | E23: Ederson reçoit 45 tirs cadrés avec xGC=38.5, encaisse 34 buts → goalsPrevented = 38.5-34 = +4.5 (surperformance) | F23: GK | G23: FALSE | H23: feat_goals_prevented_p90 | I23: z_goals_prevented_p90 | J23: goalsPrevented | K23: 4 | L23: =IFERROR(_xlfn.XLOOKUP(J23,feature_catalog!A:A,feature_catalog!A:A),"") -> goalsPrevented
A24: penaltiesSaved | B24: pk_saved_p90 | C24: vol | D24: Pénaltys arrêtés en absolu (nb de penalties stoppés sur la saison). Comptabilise uniquement les arrêts directs, pas les tirs repoussés puis marqués sur le rebond. | E24: Alisson arrête 2 pénaltys sur la saison = 2 penaltiesSaved. Stat très rare — la plupart des gardiens → 0-1/saison | F24: GK | G24: FALSE | H24: feat_pk_saved_p90 | I24: z_pk_saved_p90 | J24: penaltiesSaved | L24: =IFERROR(_xlfn.XLOOKUP(J24,feature_catalog!A:A,feature_catalog!A:A),"")
A25: highClaims | B25: high_claims_p90 | C25: vol | D25: Captages hauts réussis — le gardien sort aériennement pour attraper ou dégager un centre ou corner en hauteur, en challengeant avec des attaquants adverses. Réussi = le gardien capture ou dégage proprement sans laisser la balle traîner. | E25: Alisson sort sur un corner, capte le ballon devant Lukaku qui challengeait = 1 high claim réussi. Alisson sort, perd le duel et le ballon traîne = 0 high claim réussi | F25: GK | G25: FALSE | H25: feat_high_claims_p90 | I25: z_high_claims_p90 | J25: highClaims | L25: =IFERROR(_xlfn.XLOOKUP(J25,feature_catalog!A:A,feature_catalog!A:A),"") -> highClaims
A26: runsOut | B26: runs_out_p90 | C26: vol | D26: Sorties physiques du gardien HORS de sa surface de réparation pour intervenir sur le ballon — couper une passe longue, contrer un dribbleur en un-contre-un, dégager un ballon avant l'attaquant. Le gardien doit franchir la ligne des 18m. | E26: Neuer sort à 30m de son but pour couper un ballon dans le dos de Boateng = 1 runOut. Neuer sort à la limite de sa surface = 0 runOut | F26: GK | G26: FALSE | H26: feat_runs_out_p90 | I26: z_runs_out_p90 | J26: runsOut | L26: =IFERROR(_xlfn.XLOOKUP(J26,feature_catalog!A:A,feature_catalog!A:A),"") -> runsOut
A27: successfulRunsOut | B27: runs_out_suc_p90 | C27: vol | D27: Sous-ensemble des sorties (runsOut) réussies — le gardien récupère proprement le ballon ou le dégage sans laisser de rebond dangereux. Indicateur de précision dans les sorties hors surface. | E27: Neuer sort à 25m et capte le ballon proprement = 1 successful runOut. Neuer sort, rate le ballon, attaquant passe à côté = runOut non réussi | F27: GK | G27: FALSE | H27: feat_runs_out_suc_p90 | I27: z_runs_out_suc_p90 | J27: successfulRunsOut | L27: =IFERROR(_xlfn.XLOOKUP(J27,feature_catalog!A:A,feature_catalog!A:A),"") -> successfulRunsOut
A28: punches | B28: punches_p90 | C28: vol | D28: Dégagements au poing — action du gardien qui repousse le ballon du poing plutôt que de le capter. Souvent utilisé sur les centres difficiles à contrôler en conditions de pression. | E28: Lloris ne peut pas capter un corner tendu et repousse du poing = 1 punch | F28: GK | G28: FALSE | H28: feat_punches_p90 | I28: z_punches_p90 | J28: punches | L28: =IFERROR(_xlfn.XLOOKUP(J28,feature_catalog!A:A,feature_catalog!A:A),"") -> punches
A29: totalKeeperSweeper | B29: gk_sweeper_p90 | C29: vol | D29: Actions sweeper du gardien = toutes les interventions où le gardien agit en dernier défenseur sur un ballon dangereux arrivant derrière sa défense. Plus large que runsOut — inclut les sorties DANS la surface sur ballons filtrés. runsOut ⊂ keeperSweeper. | E29: Ederson sort à 30m = runOut ET keeperSweeper. Ederson sort à 15m (dans sa surface) pour couper un ballon filtré = keeperSweeper mais PAS runOut | F29: GK | G29: FALSE | H29: feat_gk_sweeper_p90 | I29: z_gk_sweeper_p90 | J29: totalKeeperSweeper | L29: =IFERROR(_xlfn.XLOOKUP(J29,feature_catalog!A:A,feature_catalog!A:A),"")
A30: accurateKeeperSweeper | B30: gk_sweeper_acc_p90 | C30: vol | D30: Actions sweeper réussies — sous-ensemble des keeperSweeper où le gardien récupère ou dégage proprement le ballon arrivant derrière la défense. Indicateur de précision du jeu en sweeper keeper. | E30: Ederson sort en sweeper et capte proprement le ballon filtré = 1 accurate keeperSweeper. Ederson sort, manque le ballon = keeperSweeper non réussi | F30: GK | G30: FALSE | H30: feat_gk_sweeper_acc_p90 | I30: z_gk_sweeper_acc_p90 | J30: accurateKeeperSweeper | L30: =IFERROR(_xlfn.XLOOKUP(J30,feature_catalog!A:A,feature_catalog!A:A),"")
A31: accurateLongBallsPercentage | B31: gk_long_balls_pct | C31: pct | D31: % longues passes réussies du gardien — passes longues réussies / tentées. Indicateur clé du gardien relanceur ou sweeper keeper qui participe à la construction. | E31: Ederson joue 8 longues passes, 6 arrivent à un coéquipier = 75% gk_long_balls_pct | F31: GK | G31: FALSE | H31: feat_gk_long_balls_pct | I31: z_gk_long_balls_pct | J31: accurateLongBallsPercentage | L31: =IFERROR(_xlfn.XLOOKUP(J31,feature_catalog!A:A,feature_catalog!A:A),"") -> accurateLongBallsPercentage
